Workbook

Sheet INVOICE
A1: COMMERCIAL INVOICE
A3: Shipper/Exporter | D3: Invoice No. and Date
A4: Riesti Corporation | D4: RIE003 Dated: Aug, 05th, 2026
A5: #401, 775, Gyeongin-ro, Yeongdeungpo-gu, Seoul, Republic of Korea
A6: Contact Point : Henry | D6: L/C No. and Date
A7: E-mail :Henry@riesti.com
A8: TEL : 82-70-8733-7930, FAX : 82-070-7614-3544
A9: Consignee | D9: Buyer (if other than consignee)
A10: RIESTI GLOBAL CO., LTD
A11: 117 Tan Cang, Thanh My Tay Ward, Ho Chi Minh City, Vietnam | D11: same as consignee
A13: ATTEN: PHƯƠNG THẢO
A14: TEL : (+84) 916537049
A16: Departure Date | D16: Other references
A17: =TODAY() -> 46253
A18: Carrier | B18: From
A19: Vessel | B19: Incheon
A20: To | D20: Payment Terms
A21: Vietnam | D21: T/T in advance
A23: Shipping marks
A25: Riesti global
A26: Made in South Korea
A27: C/T NO: 2PL
A28: Description of Goods | D28: Q'ty / Unit | F28: Unit price | H28: Amount | I28: EXP | J28: LOT | K28: BARCODE
A29: 1
A30: 2
A31: 3
A32: 4
A33: 5
A34: 6
A35: 7
A36: 8
A37: 9
A38: 10
A39: 11
A40: 12
... A57: 29
B59: TOTAL AMOUNT | D59: =SUM(D29:D57) -> 0 | E59: FOB | G59: =SUM(G29:G57) -> 0 | H59: =G59/D61 -> 0
C61: 1USD = | D61: =1480 -> 1480
D63: Signed by
B64: http://www.smbs.biz/
...

Sheet PACKING 
B1: PACKING LIST
B3: Shipper/Exporter | F3: Invoice No. and date
B4: =INVOICE!A4 -> Riesti Corporation | F4: =INVOICE!D4 -> RIE003 Dated: Aug, 05th, 2026
B5: =INVOICE!A5 -> #401, 775, Gyeongin-ro, Yeongdeungpo-gu, Seoul, Republic of Korea
B6: =INVOICE!A6 -> Contact Point : Henry
B7: =INVOICE!A7 -> E-mail :Henry@riesti.com
B8: =INVOICE!A8 -> TEL : 82-70-8733-7930, FAX : 82-070-7614-3544
B9: Consignee | F9: Buyer (if other than consignee)
B10: =INVOICE!A10 -> RIESTI GLOBAL CO., LTD
B11: =INVOICE!A11 -> 117 Tan Cang, Thanh My Tay Ward, Ho Chi Minh City, Vietnam | F11: =INVOICE!D11 -> same as consignee
B13: =INVOICE!A13 -> ATTEN: PHƯƠNG THẢO
B14: =INVOICE!A14 -> TEL : (+84) 916537049
B16: Departure Date | F16: Other references
B17: =INVOICE!A17 -> 46253
D18: From
B19: =INVOICE!A19 -> Vessel | D19: =INVOICE!B19 -> Incheon
B20: To
B21: =INVOICE!A21 -> Vietnam
B23: Shipping marks | F23: Q'ty / Unit
B24: Riesti global | G24: Net Weight | H24: Gross Weight
B25: =INVOICE!A27 -> C/T NO: 2PL
B26: Made in South Korea
C28: =INVOICE!B29 -> 0 | F28: =INVOICE!D29 -> 0 | G28: =H28*0.88 -> 19.36 | H28: 22 | I28: 3
C29: unpa Bubi Bubi Butter Lip Balm | F29: 10
C30: =INVOICE!B30 -> 0 | F30: 780 | G30: =H30*0.88 -> 8.36 | H30: =I30*J30 -> 9.5 | I30: 1 | J30: 9.5
C31: =INVOICE!B31 -> 0 | F31: 410 | G31: =H31*0.88 -> 6.776 | H31: =I31*J31 -> 7.7 | I31: 1 | J31: 7.7
C32: =INVOICE!B32 -> 0 | F32: 240 | G32: =H32*0.88 -> 4.84 | H32: =I32*J32 -> 5.5 | I32: 1 | J32: 5.5
C33: =INVOICE!B36 -> 0 | F33: =INVOICE!D36 -> 0 | G33: =H33*0.88 -> 28.16 | H33: =I33*J33 -> 32 | I33: 4 | J33: 8
C34: =INVOICE!B37 -> 0 | F34: =INVOICE!D37 -> 0 | G34: =H34*0.88 -> 7.92 | H34: =I34*J34 -> 9 | I34: 3 | J34: 3
C35: =INVOICE!B38 -> 0 | F35: =INVOICE!D38 -> 0 | G35: =H35*0.88 -> 28.16 | H35: =I35*J35 -> 32 | I35: 4 | J35: 8
C36: =INVOICE!B39 -> 0 | F36: =INVOICE!D39 -> 0 | G36: =H36*0.88 -> 28.16 | H36: =I36*J36 -> 32 | I36: 4 | J36: 8
C37: =INVOICE!B40 -> 0 | F37: =INVOICE!D40 -> 0 | G37: =H37*0.88 -> 23.76 | H37: =I37*J37 -> 27 | I37: 3 | J37: 9
C38: =INVOICE!B41 -> 0 | F38: =INVOICE!D41 -> 0 | G38: =H38*0.88 -> 7.92 | H38: =I38*J38 -> 9 | I38: 1 | J38: 9
C39: =INVOICE!B42 -> 0 | F39: =INVOICE!D42 -> 0 | G39: =H39*0.88 -> 23.76 | H39: =I39*J39 -> 27 | I39: 3 | J39: 9
C40: =INVOICE!B43 -> 0 | F40: =INVOICE!D43 -> 0 | G40: =H40*0.88 -> 47.52 | H40: =I40*J40 -> 54 | I40: 6 | J40: 9
C41: =INVOICE!B44 -> 0 | F41: =INVOICE!D44 -> 0 | G41: =H41*0.88 -> 15.84 | H41: =I41*J41 -> 18 | I41: 2 | J41: 9
C42: =INVOICE!B45 -> 0 | F42: =INVOICE!D45 -> 0 | G42: =H42*0.88 -> 55.44 | H42: =I42*J42 -> 63 | I42: 7 | J42: 9
C43: =INVOICE!B46 -> 0 | F43: =INVOICE!D46 -> 0 | G43: =H43*0.88 -> 15.84 | H43: =I43*J43 -> 18 | I43: 2 | J43: 9
C44: =INVOICE!B47 -> 0 | F44: =INVOICE!D47 -> 0 | G44: =H44*0.88 -> 7.128 | H44: 8.1 | I44: 1 | J44: 8.1
C45: =INVOICE!B48 -> 0 | F45: =INVOICE!D48 -> 0
...
